Workbook

Sheet Rules
A1: Aim
A2: Level or prior knowledge
A3: How often touches methods, classes or packages

Sheet Repository
A1: Reposotory Id | B1: Name | C1: Total Commits | D1: Number of New Start Developer Five or more | E1: Number of original Developers | F1: Number of New Start less than five | G1: Number of Commits five or more | H1: Average
A2: 1 | B2: acs-aem-commons | C2: 1362 | D2: =COUNTIF('Rep New Start Dev >= 5'!A:A,Table1[[#This Row],[Reposotory Id]]) -> 37 | E2: =SUMIF('Repo Start Developer'!A:A,Table1[[#This Row],[Reposotory Id]],'Repo Start Developer'!C:C) -> 7 | F2: =COUNTIF('Rep New Start Dev <5'!A:A,Table1[[#This Row],[Reposotory Id]]) -> 174 | G2: =SUMIF('Rep New Start Dev >= 5'!A:A,Table1[[#This Row],[Reposotory Id]],'Rep New Start Dev >= 5'!E:E) -> 804 | H2: =Table1[[#This Row],[Number of Commits five or more]]/Table1[[#This Row],[Number of New Start Developer Five or more]] -> 21.72973
A3: 2 | B3: acs-packaging | C3: 1880 | D3: =COUNTIF('Rep New Start Dev >= 5'!A:A,Table1[[#This Row],[Reposotory Id]]) -> 64 | E3: =SUMIF('Repo Start Developer'!A:A,Table1[[#This Row],[Reposotory Id]],'Repo Start Developer'!C:C) -> 6 | F3: =COUNTIF('Rep New Start Dev <5'!A:A,Table1[[#This Row],[Reposotory Id]]) -> 74 | G3: =SUMIF('Rep New Start Dev >= 5'!A:A,Table1[[#This Row],[Reposotory Id]],'Rep New Start Dev >= 5'!E:E) -> 1588 | H3: =Table1[[#This Row],[Number of Commits five or more]]/Table1[[#This Row],[Number of New Start Developer Five or more]] -> 24.8125
A4: 3 | B4: activiti | C4: 5177 | D4: =COUNTIF('Rep New Start Dev >= 5'!A:A,Table1[[#This Row],[Reposotory Id]]) -> 54 | E4: =SUMIF('Repo Start Developer'!A:A,Table1[[#This Row],[Reposotory Id]],'Repo Start Developer'!C:C) -> 21 | F4: =COUNTIF('Rep New Start Dev <5'!A:A,Table1[[#This Row],[Reposotory Id]]) -> 194 | G4: =SUMIF('Rep New Start Dev >= 5'!A:A,Table1[[#This Row],[Reposotory Id]],'Rep New Start Dev >= 5'!E:E) -> 2578 | H4: =Table1[[#This Row],[Number of Commits five or more]]/Table1[[#This Row],[Number of New Start Developer Five or more]] -> 47.740741
A5: 4 | B5: aem-core-wcm-components | C5: 672 | D5: =COUNTIF('Rep New Start Dev >= 5'!A:A,Table1[[#This Row],[Reposotory Id]]) -> 24 | E5: =SUMIF('Repo Start Developer'!A:A,Table1[[#This Row],[Reposotory Id]],'Repo Start Developer'!C:C) -> 3 | F5: =COUNTIF('Rep New Start Dev <5'!A:A,Table1[[#This Row],[Reposotory Id]]) -> 102 | G5: =SUMIF('Rep New Start Dev >= 5'!A:A,Table1[[#This Row],[Reposotory Id]],'Rep New Start Dev >= 5'!E:E) -> 415 | H5: =Table1[[#This Row],[Number of Commits five or more]]/Table1[[#This Row],[Number of New Start Developer Five or more]] -> 17.291667
A6: 5 | B6: ambari | C6: 10226 | D6: =COUNTIF('Rep New Start Dev >= 5'!A:A,Table1[[#This Row],[Reposotory Id]]) -> 103 | E6: =SUMIF('Repo Start Developer'!A:A,Table1[[#This Row],[Reposotory Id]],'Repo Start Developer'!C:C) -> 3 | F6: =COUNTIF('Rep New Start Dev <5'!A:A,Table1[[#This Row],[Reposotory Id]]) -> 116 | G6: =SUMIF('Rep New Start Dev >= 5'!A:A,Table1[[#This Row],[Reposotory Id]],'Rep New Start Dev >= 5'!E:E) -> 9452 | H6: =Table1[[#This Row],[Number of Commits five or more]]/Table1[[#This Row],[Number of New Start Developer Five or more]] -> 91.76699
A7: 6 | B7: antlr4 | C7: 3291 | D7: =COUNTIF('Rep New Start Dev >= 5'!A:A,Table1[[#This Row],[Reposotory Id]]) -> 66 | E7: =SUMIF('Repo Start Developer'!A:A,Table1[[#This Row],[Reposotory Id]],'Repo Start Developer'!C:C) -> 4 | F7: =COUNTIF('Rep New Start Dev <5'!A:A,Table1[[#This Row],[Reposotory Id]]) -> 327 | G7: =SUMIF('Rep New Start Dev >= 5'!A:A,Table1[[#This Row],[Reposotory Id]],'Rep New Start Dev >= 5'!E:E) -> 1435 | H7: =Table1[[#This Row],[Number of Commits five or more]]/Table1[[#This Row],[Number of New Start Developer Five or more]] -> 21.742424
A8: 7 | B8: avro | C8: 1595 | D8: =COUNTIF('Rep New Start Dev >= 5'!A:A,Table1[[#This Row],[Reposotory Id]]) -> 50 | E8: =SUMIF('Repo Start Developer'!A:A,Table1[[#This Row],[Reposotory Id]],'Repo Start Developer'!C:C) -> 3 | F8: =COUNTIF('Rep New Start Dev <5'!A:A,Table1[[#This Row],[Reposotory Id]]) -> 340 | G8: =SUMIF('Rep New Start Dev >= 5'!A:A,Table1[[#This Row],[Reposotory Id]],'Rep New Start Dev >= 5'!E:E) -> 998 | H8: =Table1[[#This Row],[Number of Commits five or more]]/Table1[[#This Row],[Number of New Start Developer Five or more]] -> 19.96
A9: 8 | B9: camel-spring-boot | C9: 8901 | D9: =COUNTIF('Rep New Start Dev >= 5'!A:A,Table1[[#This Row],[Reposotory Id]]) -> 161 | E9: =SUMIF('Repo Start Developer'!A:A,Table1[[#This Row],[Reposotory Id]],'Repo Start Developer'!C:C) -> 6 | F9: =COUNTIF('Rep New Start Dev <5'!A:A,Table1[[#This Row],[Reposotory Id]]) -> 593 | G9: =SUMIF('Rep New Start Dev >= 5'!A:A,Table1[[#This Row],[Reposotory Id]],'Rep New Start Dev >= 5'!E:E) -> 5602 | H9: =Table1[[#This Row],[Number of Commits five or more]]/Table1[[#This Row],[Number of New Start Developer Five or more]] -> 34.795031
A10: 9 | B10: commons-lang | C10: 1738 | D10: =COUNTIF('Rep New Start Dev >= 5'!A:A,Table1[[#This Row],[Reposotory Id]]) -> 37 | E10: =SUMIF('Repo Start Developer'!A:A,Table1[[#This Row],[Reposotory Id]],'Repo Start Developer'!C:C) -> 8 | F10: =COUNTIF('Rep New Start Dev <5'!A:A,Table1[[#This Row],[Reposotory Id]]) -> 200 | G10: =SUMIF('Rep New Start Dev >= 5'!A:A,Table1[[#This Row],[Reposotory Id]],'Rep New Start Dev >= 5'!E:E) -> 853 | H10: =Table1[[#This Row],[Number of Commits five or more]]/Table1[[#This Row],[Number of New Start Developer Five or more]] -> 23.054054
A11: 10 | B11: cxf | C11: 2644 | D11: =COUNTIF('Rep New Start Dev >= 5'!A:A,Table1[[#This Row],[Reposotory Id]]) -> 28 | E11: =SUMIF('Repo Start Developer'!A:A,Table1[[#This Row],[Reposotory Id]],'Repo Start Developer'!C:C) -> 15 | F11: =COUNTIF('Rep New Start Dev <5'!A:A,Table1[[#This Row],[Reposotory Id]]) -> 201 | G11: =SUMIF('Rep New Start Dev >= 5'!A:A,Table1[[#This Row],[Reposotory Id]],'Rep New Start Dev >= 5'!E:E) -> 931 | H11: =Table1[[#This Row],[Number of Commits five or more]]/Table1[[#This Row],[Number of New Start Developer Five or more]] -> 33.25
A12: 11 | B12: druid | C12: 1895 | D12: =COUNTIF('Rep New Start Dev >= 5'!A:A,Table1[[#This Row],[Reposotory Id]]) -> 39 | E12: =SUMIF('Repo Start Developer'!A:A,Table1[[#This Row],[Reposotory Id]],'Repo Start Developer'!C:C) -> 5 | F12: =COUNTIF('Rep New Start Dev <5'!A:A,Table1[[#This Row],[Reposotory Id]]) -> 269 | G12: =SUMIF('Rep New Start Dev >= 5'!A:A,Table1[[#This Row],[Reposotory Id]],'Rep New Start Dev >= 5'!E:E) -> 952 | H12: =Table1[[#This Row],[Number of Commits five or more]]/Table1[[#This Row],[Number of New Start Developer Five or more]] -> 24.410256
A13: 12 | B13: elasticsearch | C13: 17325 | D13: =COUNTIF('Rep New Start Dev >= 5'!A:A,Table1[[#This Row],[Reposotory Id]]) -> 257 | E13: =SUMIF('Repo Start Developer'!A:A,Table1[[#This Row],[Reposotory Id]],'Repo Start Developer'!C:C) -> 12 | F13: =COUNTIF('Rep New Start Dev <5'!A:A,Table1[[#This Row],[Reposotory Id]]) -> 1719 | G13: =SUMIF('Rep New Start Dev >= 5'!A:A,Table1[[#This Row],[Reposotory Id]],'Rep New Start Dev >= 5'!E:E) -> 13193 | H13: =Table1[[#This Row],[Number of Commits five or more]]/Table1[[#This Row],[Number of New Start Developer Five or more]] -> 51.33463
... A35: 34 | B35: storm | C35: 2158 | D35: =COUNTIF('Rep New Start Dev >= 5'!A:A,Table1[[#This Row],[Reposotory Id]]) -> 34 | E35: =SUMIF('Repo Start Developer'!A:A,Table1[[#This Row],[Reposotory Id]],'Repo Start Developer'!C:C) -> 21 | F35: =COUNTIF('Rep New Start Dev <5'!A:A,Table1[[#This Row],[Reposotory Id]]) -> 108 | G35: =SUMIF('Rep New Start Dev >= 5'!A:A,Table1[[#This Row],[Reposotory Id]],'Rep New Start Dev >= 5'!E:E) -> 681 | H35: =Table1[[#This Row],[Number of Commits five or more]]/Table1[[#This Row],[Number of New Start Developer Five or more]] -> 20.029412
A36: 35 | B36: iotdb | C36: 360 | D36: =COUNTIF('Rep New Start Dev >= 5'!A:A,Table1[[#This Row],[Reposotory Id]]) -> 0 | E36: =SUMIF('Repo Start Developer'!A:A,Table1[[#This Row],[Reposotory Id]],'Repo Start Developer'!C:C) -> 14 | F36: =COUNTIF('Rep New Start Dev <5'!A:A,Table1[[#This Row],[Reposotory Id]]) -> 0 | G36: =SUMIF('Rep New Start Dev >= 5'!A:A,Table1[[#This Row],[Reposotory Id]],'Rep New Start Dev >= 5'!E:E) -> 0
A37: 36 | B37: hive | C37: 568 | D37: =COUNTIF('Rep New Start Dev >= 5'!A:A,Table1[[#This Row],[Reposotory Id]]) -> 5 | E37: =SUMIF('Repo Start Developer'!A:A,Table1[[#This Row],[Reposotory Id]],'Repo Start Developer'!C:C) -> 7 | F37: =COUNTIF('Rep New Start Dev <5'!A:A,Table1[[#This Row],[Reposotory Id]]) -> 0 | G37: =SUMIF('Rep New Start Dev >= 5'!A:A,Table1[[#This Row],[Reposotory Id]],'Rep New Start Dev >= 5'!E:E) -> 257 | H37: =Table1[[#This Row],[Number of Commits five or more]]/Table1[[#This Row],[Number of New Start Developer Five or more]] -> 51.4
A38: 37 | B38: pulsar | C38: 835 | D38: =COUNTIF('Rep New Start Dev >= 5'!A:A,Table1[[#This Row],[Reposotory Id]]) -> 15 | E38: =SUMIF('Repo Start Developer'!A:A,Table1[[#This Row],[Reposotory Id]],'Repo Start Developer'!C:C) -> 18 | F38: =COUNTIF('Rep New Start Dev <5'!A:A,Table1[[#This Row],[Reposotory Id]]) -> 12 | G38: =SUMIF('Rep New Start Dev >= 5'!A:A,Table1[[#This Row],[Reposotory Id]],'Rep New Start Dev >= 5'!E:E) -> 384 | H38: =Table1[[#This Row],[Number of Commits five or more]]/Table1[[#This Row],[Number of New Start Developer Five or more]] -> 25.6
A39: 38 | B39: azure-sdk-for-java | C39: 867 | D39: =COUNTIF('Rep New Start Dev >= 5'!A:A,Table1[[#This Row],[Reposotory Id]]) -> 6 | E39: =SUMIF('Repo Start Developer'!A:A,Table1[[#This Row],[Reposotory Id]],'Repo Start Developer'!C:C) -> 11 | F39: =COUNTIF('Rep New Start Dev <5'!A:A,Table1[[#This Row],[Reposotory Id]]) -> 9 | G39: =SUMIF('Rep New Start Dev >= 5'!A:A,Table1[[#This Row],[Reposotory Id]],'Rep New Start Dev >= 5'!E:E) -> 266 | H39: =Table1[[#This Row],[Number of Commits five or more]]/Table1[[#This Row],[Number of New Start Developer Five or more]] -> 44.333333
A40: 39 | B40: ignite | C40: 1113 | D40: =COUNTIF('Rep New Start Dev >= 5'!A:A,Table1[[#This Row],[Reposotory Id]]) -> 0 | E40: =SUMIF('Repo Start Developer'!A:A,Table1[[#This Row],[Reposotory Id]],'Repo Start Developer'!C:C) -> 18 | F40: =COUNTIF('Rep New Start Dev <5'!A:A,Table1[[#This Row],[Reposotory Id]]) -> 0 | G40: =SUMIF('Rep New Start Dev >= 5'!A:A,Table1[[#This Row],[Reposotory Id]],'Rep New Start Dev >= 5'!E:E) -> 0
A41: 40 | B41: cassandra | C41: 1300 | D41: =COUNTIF('Rep New Start Dev >= 5'!A:A,Table1[[#This Row],[Reposotory Id]]) -> 4 | E41: =SUMIF('Repo Start Developer'!A:A,Table1[[#This Row],[Reposotory Id]],'Repo Start Developer'!C:C) -> 5 | F41: =COUNTIF('Rep New Start Dev <5'!A:A,Table1[[#This Row],[Reposotory Id]]) -> 0 | G41: =SUMIF('Rep New Start Dev >= 5'!A:A,Table1[[#This Row],[Reposotory Id]],'Rep New Start Dev >= 5'!E:E) -> 49 | H41: =Table1[[#This Row],[Number of Commits five or more]]/Table1[[#This Row],[Number of New Start Developer Five or more]] -> 12.25
A42: 43 | B42: beam | C42: 1683 | D42: =COUNTIF('Rep New Start Dev >= 5'!A:A,Table1[[#This Row],[Reposotory Id]]) -> 8 | E42: =SUMIF('Repo Start Developer'!A:A,Table1[[#This Row],[Reposotory Id]],'Repo Start Developer'!C:C) -> 68 | F42: =COUNTIF('Rep New Start Dev <5'!A:A,Table1[[#This Row],[Reposotory Id]]) -> 36 | G42: =SUMIF('Rep New Start Dev >= 5'!A:A,Table1[[#This Row],[Reposotory Id]],'Rep New Start Dev >= 5'!E:E) -> 182 | H42: =Table1[[#This Row],[Number of Commits five or more]]/Table1[[#This Row],[Number of New Start Developer Five or more]] -> 22.75
A43: 44 | B43: datahub | C43: 5292 | D43: =COUNTIF('Rep New Start Dev >= 5'!A:A,Table1[[#This Row],[Reposotory Id]]) -> 110 | E43: =SUMIF('Repo Start Developer'!A:A,Table1[[#This Row],[Reposotory Id]],'Repo Start Developer'!C:C) -> 7 | F43: =COUNTIF('Rep New Start Dev <5'!A:A,Table1[[#This Row],[Reposotory Id]]) -> 405 | G43: =SUMIF('Rep New Start Dev >= 5'!A:A,Table1[[#This Row],[Reposotory Id]],'Rep New Start Dev >= 5'!E:E) -> 4132 | H43: =Table1[[#This Row],[Number of Commits five or more]]/Table1[[#This Row],[Number of New Start Developer Five or more]] -> 37.563636
A44: 46 | B44: doris | C44: 2739 | D44: =COUNTIF('Rep New Start Dev >= 5'!A:A,Table1[[#This Row],[Reposotory Id]]) -> 90 | E44: =SUMIF('Repo Start Developer'!A:A,Table1[[#This Row],[Reposotory Id]],'Repo Start Developer'!C:C) -> 11 | F44: =COUNTIF('Rep New Start Dev <5'!A:A,Table1[[#This Row],[Reposotory Id]]) -> 219 | G44: =SUMIF('Rep New Start Dev >= 5'!A:A,Table1[[#This Row],[Reposotory Id]],'Rep New Start Dev >= 5'!E:E) -> 2141 | H44: =Table1[[#This Row],[Number of Commits five or more]]/Table1[[#This Row],[Number of New Start Developer Five or more]] -> 23.788889
A45: 47 | B45: lucene | C45: 2167 | D45: =COUNTIF('Rep New Start Dev >= 5'!A:A,Table1[[#This Row],[Reposotory Id]]) -> 27 | E45: =SUMIF('Repo Start Developer'!A:A,Table1[[#This Row],[Reposotory Id]],'Repo Start Developer'!C:C) -> 10 | F45: =COUNTIF('Rep New Start Dev <5'!A:A,Table1[[#This Row],[Reposotory Id]]) -> 3 | G45: =SUMIF('Rep New Start Dev >= 5'!A:A,Table1[[#This Row],[Reposotory Id]],'Rep New Start Dev >= 5'!E:E) -> 1810 | H45: =Table1[[#This Row],[Number of Commits five or more]]/Table1[[#This Row],[Number of New Start Developer Five or more]] -> 67.037037
A46: 48 | B46: pinot | C46: 2013 | D46: =COUNTIF('Rep New Start Dev >= 5'!A:A,Table1[[#This Row],[Reposotory Id]]) -> 23 | E46: =SUMIF('Repo Start Developer'!A:A,Table1[[#This Row],[Reposotory Id]],'Repo Start Developer'!C:C) -> 9 | F46: =COUNTIF('Rep New Start Dev <5'!A:A,Table1[[#This Row],[Reposotory Id]]) -> 14 | G46: =SUMIF('Rep New Start Dev >= 5'!A:A,Table1[[#This Row],[Reposotory Id]],'Rep New Start Dev >= 5'!E:E) -> 852 | H46: =Table1[[#This Row],[Number of Commits five or more]]/Table1[[#This Row],[Number of New Start Developer Five or more]] -> 37.043478
A47: 50 | B47: airbyte-platform | C47: 8276 | D47: =COUNTIF('Rep New Start Dev >= 5'!A:A,Table1[[#This Row],[Reposotory Id]]) -> 147 | E47: =SUMIF('Repo Start Developer'!A:A,Table1[[#This Row],[Reposotory Id]],'Repo Start Developer'!C:C) -> 30 | F47: =COUNTIF('Rep New Start Dev <5'!A:A,Table1[[#This Row],[Reposotory Id]]) -> 457 | G47: =SUMIF('Rep New Start Dev >= 5'!A:A,Table1[[#This Row],[Reposotory Id]],'Rep New Start Dev >= 5'!E:E) -> 5582 | H47: =Table1[[#This Row],[Number of Commits five or more]]/Table1[[#This Row],[Number of New Start Developer Five or more]] -> 37.972789
A48: 51 | B48: frameworks_base | C48: 353 | D48: =COUNTIF('Rep New Start Dev >= 5'!A:A,Table1[[#This Row],[Reposotory Id]]) -> 1 | E48: =SUMIF('Repo Start Developer'!A:A,Table1[[#This Row],[Reposotory Id]],'Repo Start Developer'!C:C) -> 40 | F48: =COUNTIF('Rep New Start Dev <5'!A:A,Table1[[#This Row],[Reposotory Id]]) -> 19 | G48: =SUMIF('Rep New Start Dev >= 5'!A:A,Table1[[#This Row],[Reposotory Id]],'Rep New Start Dev >= 5'!E:E) -> 8 | H48: =Table1[[#This Row],[Number of Commits five or more]]/Table1[[#This Row],[Number of New Start Developer Five or more]] -> 8
D49: =AVERAGE(Table1[Number of New Start Developer Five or more]) -> 50.489362 | H49: =AVERAGE(Table1[Average]) -> 31.745677
G50: Mode
G51: Medium
A53: Take on repository measure rate of knowledge
A54: Start with graph for each | C54: As size
A55: See if can cluster
A56: What level does knowledge peak at | C56: Percentage and absolute
C57: Percentage and absolute touched after a year or six months
A58: How colated is the knowledge, siloed | C58: Largely in one or two modules
A59: In clean code base do they learn more
A60: Measure through static analysis clean code base
A63: Comment code | B63: Code follow linting rules
A64: Clean code more comments
...

Sheet File Commits Pivot
A3: Row Labels | B3: Count of file_id
A4: 1 | B4: 131 | C4: =SUM(B$4:B4)/GETPIVOTDATA("file_id",$A$3) -> 0.0035727922
A5: 2 | B5: 848 | C5: =SUM(B$4:B5)/GETPIVOTDATA("file_id",$A$3) -> 0.026700485
A6: 3 | B6: 4950 | C6: =SUM(B$4:B6)/GETPIVOTDATA("file_id",$A$3) -> 0.16170294
A7: 4 | B7: 970 | C7: =SUM(B$4:B7)/GETPIVOTDATA("file_id",$A$3) -> 0.18815797
A8: 5 | B8: 2333 | C8: =SUM(B$4:B8)/GETPIVOTDATA("file_id",$A$3) -> 0.2517864
A9: 6 | B9: 4037 | C9: =SUM(B$4:B9)/GETPIVOTDATA("file_id",$A$3) -> 0.3618884
A10: 7 | B10: 7977 | C10: =SUM(B$4:B10)/GETPIVOTDATA("file_id",$A$3) -> 0.5794469
A11: 8 | B11: 428 | C11: =SUM(B$4:B11)/GETPIVOTDATA("file_id",$A$3) -> 0.59111984
A12: 9 | B12: 573 | C12: =SUM(B$4:B12)/GETPIVOTDATA("file_id",$A$3) -> 0.6067474
A13: 10 | B13: 957 | C13: =SUM(B$4:B13)/GETPIVOTDATA("file_id",$A$3) -> 0.63284787
A14: 11 | B14: 146 | C14: =SUM(B$4:B14)/GETPIVOTDATA("file_id",$A$3) -> 0.63682976
A15: 12 | B15: 1229 | C15: =SUM(B$4:B15)/GETPIVOTDATA("file_id",$A$3) -> 0.67034855
... A28: 25 | B28: 167 | C28: =SUM(B$4:B28)/GETPIVOTDATA("file_id",$A$3) -> 0.85406098
A29: 26 | B29: 90
A30: 27 | B30: 95
A31: 28 | B31: 748
A32: 29 | B32: 58
A33: 30 | B33: 309
A34: 31 | B34: 71
A35: 32 | B35: 49
A36: 33 | B36: 50
A37: 34 | B37: 66
A38: 35 | B38: 498
A39: 36 | B39: 161
A40: 37 | B40: 28
... A295: 1281 | B295: 1
A296: Grand Total | B296: 36666

Sheet File Commit New
A3: Row Labels | B3: Count of file_id
A4: 1 | B4: 131 | C4: =SUM(B$4:B4)/GETPIVOTDATA("file_id",$A$3) -> 0.0038038271
A5: 2 | B5: 403 | C5: =SUM(B$4:B5)/GETPIVOTDATA("file_id",$A$3) -> 0.015505677
A6: 3 | B6: 4738 | C6: =SUM(B$4:B6)/GETPIVOTDATA("file_id",$A$3) -> 0.15308226
A7: 4 | B7: 825 | C7: =SUM(B$4:B7)/GETPIVOTDATA("file_id",$A$3) -> 0.17703766
A8: 5 | B8: 2256 | C8: =SUM(B$4:B8)/GETPIVOTDATA("file_id",$A$3) -> 0.24254479
A9: 6 | B9: 3181 | C9: =SUM(B$4:B9)/GETPIVOTDATA("file_id",$A$3) -> 0.334911
A10: 7 | B10: 8078 | C10: =SUM(B$4:B10)/GETPIVOTDATA("file_id",$A$3) -> 0.56947066
A11: 8 | B11: 366 | C11: =SUM(B$4:B11)/GETPIVOTDATA("file_id",$A$3) -> 0.58009814
A12: 9 | B12: 514 | C12: =SUM(B$4:B12)/GETPIVOTDATA("file_id",$A$3) -> 0.59502308
A13: 10 | B13: 901
A14: 11 | B14: 124
A15: 12 | B15: 967
A16: 13 | B16: 229
A17: 14 | B17: 1842
A18: 15 | B18: 415
A19: 16 | B19: 132
A20: 17 | B20: 141
A21: 18 | B21: 490
A22: 19 | B22: 85
A23: 20 | B23: 284
A24: 21 | B24: 821
... A905: 240235 | B905: 1
A906: Grand Total | B906: 34439

Sheet FIle Commits
A1: file_id | B1: count(commit_id) | E1: file_id | F1: count(commit_id)
A2: 106692 | B2: 1 | E2: 106692 | F2: 1
A3: 106693 | B3: 1 | E3: 106693 | F3: 1
A4: 106695 | B4: 1 | E4: 106695 | F4: 1
A5: 106696 | B5: 1 | E5: 106696 | F5: 1
A6: 106701 | B6: 1 | E6: 106701 | F6: 1
A7: 106702 | B7: 1 | E7: 106702 | F7: 1
A8: 106703 | B8: 1 | E8: 106703 | F8: 1
A9: 106704 | B9: 1 | E9: 106704 | F9: 1
A10: 106705 | B10: 1 | E10: 106705 | F10: 1
A11: 106706 | B11: 1 | E11: 106706 | F11: 1
A12: 106708 | B12: 1 | E12: 106708 | F12: 1
A13: 106709 | B13: 1 | E13: 106709 | F13: 1
... A34440: 71959 | B34440: 49 | E34440: 84212 | F34440: 240235
A34441: 71971 | B34441: 49
A34442: 71973 | B34442: 49
A34443: 72000 | B34443: 49
A34444: 72037 | B34444: 49
A34445: 72104 | B34445: 49
A34446: 72132 | B34446: 49
A34447: 72158 | B34447: 49
A34448: 72223 | B34448: 49
A34449: 72225 | B34449: 49
A34450: 72227 | B34450: 49
A34451: 72232 | B34451: 49
A34452: 72237 | B34452: 49
... A36667: 77598 | B36667: 1281

Sheet Rep New Start Dev <5
A1: Repository_id | B1: Rep Name | C1: Developer Id | D1: Dev Name | E1: Commits
A2: 1 | B2: acs-aem-commons | C2: 10 | D2: Kaushal Mall | E2: 4
A3: 1 | B3: acs-aem-commons | C3: 20 | D3: Michael Kreis | E3: 4
A4: 1 | B4: acs-aem-commons | C4: 24 | D4: davidjgonzalez@gmail.com | E4: 4
A5: 1 | B5: acs-aem-commons | C5: 47 | D5: Joseph Rignanese | E5: 4
A6: 1 | B6: acs-aem-commons | C6: 59 | D6: Shamal Roy | E6: 4
A7: 1 | B7: acs-aem-commons | C7: 70 | D7: Jeff Shelley | E7: 4
A8: 1 | B8: acs-aem-commons | C8: 71 | D8: Roy Teeuwen | E8: 4
A9: 1 | B9: acs-aem-commons | C9: 96 | D9: Steve Maris | E9: 4
A10: 1 | B10: acs-aem-commons | C10: 97 | D10: Niek Raaijmakers | E10: 4
A11: 1 | B11: acs-aem-commons | C11: 136 | D11: anasidorovich | E11: 4
A12: 1 | B12: acs-aem-commons | C12: 160 | D12: YentlFrickx | E12: 4
A13: 1 | B13: acs-aem-commons | C13: 196 | D13: Bart | E13: 4
... A403: 46 | B403: doris | C403: 11399 | D403: xiaoni | E403: 4
A404: 46 | B404: doris | C404: 11416 | D404: 924060929 | E404: 4
A405: 46 | B405: doris | C405: 11434 | D405: Userwhite | E405: 4
A406: 46 | B406: doris | C406: 11439 | D406: ChPi | E406: 4
A407: 46 | B407: doris | C407: 11501 | D407: SleepyBear | E407: 4
A408: 46 | B408: doris | C408: 11503 | D408: Heng Zhao | E408: 4
A409: 46 | B409: doris | C409: 11541 | D409: Xin Liao | E409: 4
A410: 46 | B410: doris | C410: 11546 | D410: kangshisen | E410: 4
A411: 46 | B411: doris | C411: 11554 | D411: Jibing-Li | E411: 4
A412: 46 | B412: doris | C412: 11562 | D412: Lightman | E412: 4
A413: 46 | B413: doris | C413: 11570 | D413: chenlinzhong | E413: 4
A414: 46 | B414: doris | C414: 11589 | D414: yixiutt | E414: 4
A415: 48 | B415: pinot | C415: 11687 | D415: Kexin Nie | E415: 4
A416: 50 | B416: airbyte-platform | C416: 11798 | D416: Daniel Dubinin | E416: 4
... A798: 13 | B798: eventmesh | C798: 5525 | D798: liujun | E798: 3
A799: 13 | B799: eventmesh | C799: 5554 | D799: 774263648 | E799: 3
A800: 13 | B800: eventmesh | C800: 5559 | D800: wanght001 | E800: 3
A801: 13 | B801: eventmesh | C801: 5567 | D801: CalebZYC | E801: 3
A802: 13 | B802: eventmesh | C802: 5581 | D802: Tarun Samanta | E802: 3
A803: 13 | B803: eventmesh | C803: 5586 | D803: Preet Angad Singh Nanda | E803: 3
A804: 13 | B804: eventmesh | C804: 5623 | D804: bsh786 | E804: 3
A805: 13 | B805: eventmesh | C805: 5627 | D805: Monish Parate | E805: 3
A806: 13 | B806: eventmesh | C806: 5648 | D806: Kartik Tayal | E806: 3
A807: 13 | B807: eventmesh | C807: 5656 | D807: zhengpeng | E807: 3
A808: 13 | B808: eventmesh | C808: 5667 | D808: HeeHunLee | E808: 3
A809: 13 | B809: eventmesh | C809: 5671 | D809: tooo-bad | E809: 3
A810: 13 | B810: eventmesh | C810: 5678 | D810: Fungx | E810: 3
...

Sheet Rep New Start Dev >= 5
A1: Repository_id | B1: Rep Name | C1: Developer Id | D1: Dev Name | E1: Commits
A2: 19 | B2: intellij-community | C2: 6857 | D2: anna | E2: 1145
A3: 19 | B3: intellij-community | C3: 7147 | D3: Anna.Kozlova | E3: 1082
A4: 19 | B4: intellij-community | C4: 6821 | D4: Dmitry Jemerov | E4: 1045
A5: 8 | B5: camel-spring-boot | C5: 1787 | D5: Claus Ibsen | E5: 1031
A6: 19 | B6: intellij-community | C6: 7177 | D6: Vitaliy Bibaev | E6: 934
A7: 19 | B7: intellij-community | C7: 5870 | D7: Dominik Fay | E7: 758
A8: 12 | B8: elasticsearch | C8: 3873 | D8: Jason Tedor | E8: 742
A9: 19 | B9: intellij-community | C9: 6873 | D9: Denis Zhdanov | E9: 741
A10: 19 | B10: intellij-community | C10: 7167 | D10: Tagir Valeev | E10: 699
A11: 19 | B11: intellij-community | C11: 6891 | D11: Andrey Breslav | E11: 686
A12: 5 | B12: ambari | C12: 770 | D12: Yusaku Sako | E12: 655
A13: 19 | B13: intellij-community | C13: 6987 | D13: Konstantin Kolosovsky | E13: 647
... A1507: 1 | B1507: acs-aem-commons | C1507: 13 | D1507: Matthias Schoger | E1507: 9
A1508: 1 | B1508: acs-aem-commons | C1508: 103 | E1508: 9
A1509: 2 | B1509: acs-packaging | C1509: 282 | D1509: CezarLeahu | E1509: 9
A1510: 2 | B1510: acs-packaging | C1510: 303 | D1510: Ayman Harake | E1510: 9
A1511: 2 | B1511: acs-packaging | C1511: 337 | D1511: Damian Ujma | E1511: 9
A1512: 2 | B1512: acs-packaging | C1512: 340 | D1512: mpichura | E1512: 9
A1513: 2 | B1513: acs-packaging | C1513: 346 | D1513: SNegi01 | E1513: 9
A1514: 2 | B1514: acs-packaging | C1514: 348 | D1514: MohinishSah | E1514: 9
A1515: 3 | B1515: activiti | C1515: 405 | D1515: Bassam Al-Sarori | E1515: 9
A1516: 3 | B1516: activiti | C1516: 493 | D1516: cdeneux | E1516: 9
A1517: 4 | B1517: aem-core-wcm-components | C1517: 753 | D1517: levente | E1517: 9
A1518: 5 | B1518: ambari | C1518: 966 | D1518: Mohammad Arshad | E1518: 9
A1519: 6 | B1519: antlr4 | C1519: 1059 | D1519: Burt Harris | E1519: 9
A1520: 7 | B1520: avro | C1520: 1420 | D1520: Gabor Szadovszky | E1520: 9
... A2374: 50 | B2374: airbyte-platform | C2374: 12350 | D2374: timroes | E2374: 5

Sheet Repo New Developer
A1: Reposotory Id | B1: Name | C1: Total Commits
A2: 1 | B2: acs-aem-commons | C2: 211
A3: 2 | B3: acs-packaging | C3: 138
A4: 3 | B4: activiti | C4: 249
A5: 4 | B5: aem-core-wcm-components | C5: 127
A6: 5 | B6: ambari | C6: 219
A7: 6 | B7: antlr4 | C7: 394
A8: 7 | B8: avro | C8: 391
A9: 8 | B9: camel-spring-boot | C9: 755
A10: 9 | B10: commons-lang | C10: 238
A11: 10 | B11: cxf | C11: 230
A12: 11 | B12: druid | C12: 309
A13: 12 | B13: elasticsearch | C13: 1977
... A46: 51 | B46: frameworks_base | C46: 20

Sheet Repo Start Developer
A1: 1 | B1: acs-aem-commons | C1: 7
A2: 2 | B2: acs-packaging | C2: 6
A3: 3 | B3: activiti | C3: 21
A4: 4 | B4: aem-core-wcm-components | C4: 3
A5: 5 | B5: ambari | C5: 3
A6: 6 | B6: antlr4 | C6: 4
A7: 7 | B7: avro | C7: 3
A8: 8 | B8: camel-spring-boot | C8: 6
A9: 9 | B9: commons-lang | C9: 8
A10: 10 | B10: cxf | C10: 15
A11: 11 | B11: druid | C11: 5
A12: 12 | B12: elasticsearch | C12: 12
... A47: 51 | B47: frameworks_base | C47: 40

Sheet Databases
A1: acs-aem-commons.db | B1: datahub.db | C1: liferay-portal.db | D1: ="get "&A1 -> get acs-aem-commons.db | E1: ="get "&B1 -> get datahub.db | F1: ="get "&C1 -> get liferay-portal.db | G1: ="python main.py ../refactor_code_base/src/resource/database/"&A1 -> python main.py ../refactor_code_base/src/resource/database/acs-aem-commons.db | H1: ="python main.py ../refactor_code_base/src/resource/database/"&C1 -> python main.py ../refactor_code_base/src/resource/database/liferay-portal.db
A2: acs-packaging.db | B2: doris.db | C2: lucene.db | D2: ="get "&A2 -> get acs-packaging.db | E2: ="get "&B2 -> get doris.db | F2: ="get "&C2 -> get lucene.db | G2: ="python main.py ../refactor_code_base/src/resource/database/"&B2 -> python main.py ../refactor_code_base/src/resource/database/doris.db | H2: ="python main.py ../refactor_code_base/src/resource/database/"&C2 -> python main.py ../refactor_code_base/src/resource/database/lucene.db
A3: activiti.db | B3: druid.db | C3: maven.db | D3: ="get "&A3 -> get activiti.db | E3: ="get "&B3 -> get druid.db | F3: ="get "&C3 -> get maven.db | G3: ="python main.py ../refactor_code_base/src/resource/database/"&B3 -> python main.py ../refactor_code_base/src/resource/database/druid.db | H3: ="python main.py ../refactor_code_base/src/resource/database/"&C3 -> python main.py ../refactor_code_base/src/resource/database/maven.db
A4: aem-core-wcm-components.db | B4: elasticsearch.db | C4: media.db | D4: ="get "&A4 -> get aem-core-wcm-components.db | E4: ="get "&B4 -> get elasticsearch.db | F4: ="get "&C4 -> get media.db | G4: ="python main.py ../refactor_code_base/src/resource/database/"&B4 -> python main.py ../refactor_code_base/src/resource/database/elasticsearch.db | H4: ="python main.py ../refactor_code_base/src/resource/database/"&C4 -> python main.py ../refactor_code_base/src/resource/database/media.db
A5: airbyte-platform.db | B5: eventmesh.db | C5: mindustry.db | D5: ="get "&A5 -> get airbyte-platform.db | E5: ="get "&B5 -> get eventmesh.db | F5: ="get "&C5 -> get mindustry.db | G5: ="python main.py ../refactor_code_base/src/resource/database/"&B5 -> python main.py ../refactor_code_base/src/resource/database/eventmesh.db | H5: ="python main.py ../refactor_code_base/src/resource/database/"&C5 -> python main.py ../refactor_code_base/src/resource/database/mindustry.db
A6: alluxio.db | B6: flink.db | C6: mockito.db | D6: ="get "&A6 -> get alluxio.db | E6: ="get "&B6 -> get flink.db | F6: ="get "&C6 -> get mockito.db | G6: ="python main.py ../refactor_code_base/src/resource/database/"&B6 -> python main.py ../refactor_code_base/src/resource/database/flink.db | H6: ="python main.py ../refactor_code_base/src/resource/database/"&C6 -> python main.py ../refactor_code_base/src/resource/database/mockito.db
A7: ambari.db | B7: frameworks_base.db | C7: nacos.db | D7: ="get "&A7 -> get ambari.db | E7: ="get "&B7 -> get frameworks_base.db | F7: ="get "&C7 -> get nacos.db | G7: ="python main.py ../refactor_code_base/src/resource/database/"&B7 -> python main.py ../refactor_code_base/src/resource/database/frameworks_base.db | H7: ="python main.py ../refactor_code_base/src/resource/database/"&C7 -> python main.py ../refactor_code_base/src/resource/database/nacos.db
A8: antlr4.db | B8: groovy.db | C8: newpipe.db | D8: ="get "&A8 -> get antlr4.db | E8: ="get "&B8 -> get groovy.db | F8: ="get "&C8 -> get newpipe.db | G8: ="python main.py ../refactor_code_base/src/resource/database/"&B8 -> python main.py ../refactor_code_base/src/resource/database/groovy.db | H8: ="python main.py ../refactor_code_base/src/resource/database/"&C8 -> python main.py ../refactor_code_base/src/resource/database/newpipe.db
A9: a_refactoring-toy-example.db | B9: hadoop.db | C9: nifi.db | D9: ="get "&A9 -> get a_refactoring-toy-example.db | E9: ="get "&B9 -> get hadoop.db | F9: ="get "&C9 -> get nifi.db | G9: ="python main.py ../refactor_code_base/src/resource/database/"&B9 -> python main.py ../refactor_code_base/src/resource/database/hadoop.db | H9: ="python main.py ../refactor_code_base/src/resource/database/"&C9 -> python main.py ../refactor_code_base/src/resource/database/nifi.db
A10: automq.db | B10: hbase.db | C10: packages_apps_settings.db | D10: ="get "&A10 -> get automq.db | E10: ="get "&B10 -> get hbase.db | F10: ="get "&C10 -> get packages_apps_settings.db | G10: ="python main.py ../refactor_code_base/src/resource/database/"&B10 -> python main.py ../refactor_code_base/src/resource/database/hbase.db | H10: ="python main.py ../refactor_code_base/src/resource/database/"&C10 -> python main.py ../refactor_code_base/src/resource/database/packages_apps_settings.db
A11: avro.db | B11: hermes.db | C11: pinot.db | D11: ="get "&A11 -> get avro.db | E11: ="get "&B11 -> get hermes.db | F11: ="get "&C11 -> get pinot.db | G11: ="python main.py ../refactor_code_base/src/resource/database/"&B11 -> python main.py ../refactor_code_base/src/resource/database/hermes.db | H11: ="python main.py ../refactor_code_base/src/resource/database/"&C11 -> python main.py ../refactor_code_base/src/resource/database/pinot.db
A12: azure-sdk-for-java.db | B12: hertzbeat.db | C12: pmd.db | D12: ="get "&A12 -> get azure-sdk-for-java.db | E12: ="get "&B12 -> get hertzbeat.db | F12: ="get "&C12 -> get pmd.db | G12: ="python main.py ../refactor_code_base/src/resource/database/"&B12 -> python main.py ../refactor_code_base/src/resource/database/hertzbeat.db | H12: ="python main.py ../refactor_code_base/src/resource/database/"&C12 -> python main.py ../refactor_code_base/src/resource/database/pmd.db
A13: beam.db | B13: hive.db | C13: pulsar.db | D13: ="get "&A13 -> get beam.db | E13: ="get "&B13 -> get hive.db | F13: ="get "&C13 -> get pulsar.db | G13: ="python main.py ../refactor_code_base/src/resource/database/"&B13 -> python main.py ../refactor_code_base/src/resource/database/hive.db | H13: ="python main.py ../refactor_code_base/src/resource/database/"&C13 -> python main.py ../refactor_code_base/src/resource/database/pulsar.db
... A19: commons-lang.db | B19: kapua.db | C19: spring-cloud-alibaba.db | D19: ="get "&A19 -> get commons-lang.db | E19: ="get "&B19 -> get kapua.db | F19: ="get "&C19 -> get spring-cloud-alibaba.db | G19: ="python main.py ../refactor_code_base/src/resource/database/"&B19 -> python main.py ../refactor_code_base/src/resource/database/kapua.db | H19: ="python main.py ../refactor_code_base/src/resource/database/"&C19 -> python main.py ../refactor_code_base/src/resource/database/spring-cloud-alibaba.db
A20: cxf.db | C20: storm.db | D20: ="get "&A20 -> get cxf.db | F20: ="get "&C20 -> get storm.db | H20: ="python main.py ../refactor_code_base/src/resource/database/"&C20 -> python main.py ../refactor_code_base/src/resource/database/storm.db
G27: 4195835
G28: 3145727
G29: =(G27/G28)*G28-G27 -> 0

Sheet Intelli-J
A1: R-Cade
